<?xml version="1.0"?>
<robot name="IRED">
    <!-- link -->
    <link name="base_footprint"/>
    <link name="base_link"/>
    <link name="wheel_front_left_link"/>
    <link name="wheel_front_right_link"/>
    <link name="wheel_rear_left_link"/>
    <link name="wheel_rear_right_link"/>
    <link name="base_scan"/>
    <link name="aruco_camera_link"/>
    <link name="base_cartesian_link"/>
    
   <!-- joint -->
    <joint name="base_joint" type="fixed">
        <parent link="base_footprint"/>
        <child link="base_link"/>
        <origin xyz="0.0 0.0 0.022" rpy="0.0 0.0 0.0"/>
    </joint>

    <joint name="scan_joint" type="fixed">
        <parent link="base_link"/>
        <child link="base_scan"/>
        <origin xyz="0.0 0.0 0.265" rpy="0.0 0.0 0.0"/>
    </joint>

    <joint name="aruco_camera_joint" type="fixed">
        <parent link="base_link"/>
        <child link="aruco_camera_link"/>
        <origin xyz="0.09 0.0 0.56" rpy="-1.57 0.0 -1.57"/>
    </joint>

    <joint name="base_cartesian_joint" type="fixed">
        <parent link="base_link"/>
        <child link="base_cartesian_link"/>
        <origin xyz="0.0 0.0 0.765" rpy="0.0 0.0 0.0"/>
    </joint>

    <joint name="wheel_front_right_joint" type="continuous">
        <parent link="base_link"/>
        <child link="wheel_front_right_link"/>
        <axis xyz="0 0 1"/>
        <origin xyz="0.1454872 -0.1454872 0.0415" rpy="-1.57 0 -2.355"/>
    </joint>

    <joint name="wheel_front_left_joint" type="continuous">
        <parent link="base_link"/>
        <child link="wheel_front_left_link"/>
        <axis xyz="0 0 1"/>
        <origin xyz="0.1454872 0.1454872 0.0415" rpy="-1.57 0 -0.785"/>
    </joint>

    <joint name="wheel_rear_right_joint" type="continuous">
        <parent link="base_link"/>
        <child link="wheel_rear_right_link"/>
        <axis xyz="0 0 1"/>
        <origin xyz="-0.1454872 -0.1454872 0.0415" rpy="-1.57 0 2.355"/>
    </joint>

    <joint name="wheel_rear_left_joint" type="continuous">
        <parent link="base_link"/>
        <child link="wheel_rear_left_link"/>
        <axis xyz="0 0 1"/>
        <origin xyz="-0.1454872 0.1454872 0.0415" rpy="-1.57 0 0.785"/>
    </joint>
</robot>